Workbook

Sheet Nombres
B7: Estudiante 1 | C7: Joseph Sebastian contreras Gonzalez | D7: C.C.1 | E7: 1094221434
B9: Estudiante 2 | C9: Brenda Lucia argel adame | D9: C.C.2 | E9: 1029662929

Sheet Estado Situación Financiera
E3: C M
E4: NIT.9000000000-9
E5: Bucaramabnga Santander Colombia
N6: ANÁLISIS VERTICAL | S6: ANÁLISIS HORIZONTAL
E7: Estado de Situación Financiera | N7: DIC 2025 % | P7: DIC 2024 % | S7: VARIABLE ABSOLUTA | U7: VARIABLE RELATIVA %
E8: (Cifras expresadas en pesos colombianos – COP)
E10: Concepto | F10: Nota | G10: Al 31 de diciembre 2025 | I10: Al 31 de diciembre 2024 | K10: Al 31 de diciembre 2023
C11: Activos | G11: $ | I11: $ | K11: $
D12: Activos corrientes
E13: Efectivo y equivalentes de efectivo | F13: 6 | G13: 892450320 | I13: 1184235780 | K13: 698320450 | N13: =G13/G$26 -> 0.31861846 | P13: =I13/I$26 -> 0.49812916 | S13: =G13-I13 -> -291785460 | U13: =N13-P13 -> -0.1795107
E14: Cuentas por cobrar | F14: 7 | G14: 53870125 | I14: 28964310 | K14: 9845200 | N14: =G14/G$26 -> 0.019232462 | P14: =I14/I$26 -> 0.012183357 | S14: =G14-I14 -> 24905815 | U14: =N14-P14 -> 0.0070491044
E15: Inventarios | F15: 8 | G15: 48615980 | I15: 23754600 | K15: 4965800 | N15: =G15/G$26 -> 0.017356651 | P15: =I15/I$26 -> 0.009991979 | S15: =G15-I15 -> 24861380 | U15: =N15-P15 -> 0.0073646722
E16: Otros activos corrientes | F16: 9 | G16: 24983745 | I16: 14860250 | K16: 6210900 | N16: =G16/G$26 -> 0.0089195805 | P16: =I16/I$26 -> 0.006250718 | S16: =G16-I16 -> 10123495 | U16: =N16-P16 -> 0.0026688625
E17: Total activos corrientes | G17: 1019920170 | I17: 1251814940 | K17: 719342350 | N17: =G17/G26 -> 0.36412716 | P17: =I17/I$26 -> 0.52655522 | S17: =G17-I17 -> -231894770 | U17: =N17-P17 -> -0.16242806
D18: Activos no corrientes
E19: Propiedad, planta y equipo | F19: 10 | G19: 702365880 | I19: 398754200 | K19: 152630500 | N19: =G19/G$26 -> 0.2507554 | P19: =I19/I$26 -> 0.16772935 | S19: =G19-I19 -> 303611680 | U19: =N19-P19 -> 0.083026053
E20: Recursos naturales (títulos mineros) | F20: 11 | G20: 898740560 | I20: 612480350 | K20: 302145780 | N20: =G20/G$26 -> 0.32086418 | P20: =I20/I$26 -> 0.25762971 | S20: =G20-I20 -> 286260210 | U20: =N20-P20 -> 0.063234464
E21: Activos por derecho de uso | F21: 12 | G21: 31245900 | I21: 19845600 | K21: 9980450 | N21: =G21/G$26 -> 0.011155266 | P21: =I21/I$26 -> 0.0083477229 | S21: =G21-I21 -> 11400300 | U21: =N21-P21 -> 0.0028075431
E22: Intangibles | F22: 13 | G22: 79865430 | I22: 48620700 | K22: 21360900 | N22: =G22/G$26 -> 0.028513185 | P22: =I22/I$26 -> 0.020451492 | S22: =G22-I22 -> 31244730 | U22: =N22-P22 -> 0.0080616925
E23: Goodwill | F23: 14 | G23: 38952760 | I23: 27430500 | K23: 11245300 | N23: =G23/G$26 -> 0.013906733 | P23: =I23/I$26 -> 0.011538185 | S23: =G23-I23 -> 11522260 | U23: =N23-P23 -> 0.0023685479
E24: Otros activos no corrientes | F24: 15 | G24: 29909300 | I24: 18420600 | K24: 9780700 | N24: =G24/G$26 -> 0.010678079 | P24: =I24/I$26 -> 0.0077483202 | S24: =G24-I24 -> 11488700 | U24: =N24-P24 -> 0.002929759
E25: Total activos no corrientes | G25: 1781079830 | I25: 1125551950 | K25: 507143630 | N25: =G25/G$26 -> 0.63587284 | P25: =I25/I$26 -> 0.47344478 | S25: =G25-I25 -> 655527880 | U25: =N25-P25 -> 0.16242806
E26: Total activos | G26: 2801000000 | I26: 2377366890 | K26: 1226485980 | N26: =N25+N17 -> 1 | P26: =P25+P17 -> 1 | S26: =G26-I26 -> 423633110 | U26: =N26-P26 -> 0
C28: Pasivos
D29: Pasivos corrientes
E30: Impuestos por pagar | F30: 16 | G30: 6845320 | I30: 4960210 | K30: 2145980 | N30: =G30/G$43 -> 0.0024438843 | P30: =I30/I$43 -> 0.0020864302 | S30: =G30-I30 -> 1885110 | U30: =N30-P30 -> 0.00035745416
E31: Total pasivos corrientes | G31: 6845320 | I31: 4960210 | K31: 2145980 | N31: =G31/G$43 -> 0.0024438843 | P31: =I31/I$43 -> 0.0020864302 | S31: =G31-I31 -> 1885110 | U31: =N31-P31 -> 0.00035745416
D32: Pasivos no corrientes
E33: Obligaciones financieras | F33: 17 | G33: 0 | I33: 0 | K33: 0
E34: Total pasivos no corrientes | G34: 0 | I34: 0 | K34: 0
E35: Total pasivos | G35: 6845320 | I35: 4960210 | K35: 2145980 | N35: =G35/G$43 -> 0.0024438843 | P35: =I35/I$43 -> 0.0020864302 | S35: =G35-I35 -> 1885110 | U35: =N35-P35 -> 0.00035745416
C37: Patrimonio
E38: Obligaciones financieras (Aportes sociales) | F38: 17 | G38: 2.6392398e+09 | I38: 2.2695407e+09 | K38: 1.1392116e+09 | N38: =G38/G$43 -> 0.94224912 | P38: =I38/I$43 -> 0.95464468 | S38: =G38-I38 -> 3.6969914e+08 | U38: =N38-P38 -> -0.012395559
E39: Reserva legal | F39: 18 | G39: 33476531 | I39: 30006607 | K39: 28824100 | N39: =G39/G$43 -> 0.011951635 | P39: =I39/I$43 -> 0.012621782 | S39: =G39-I39 -> 3469924.3 | U39: =N39-P39 -> -0.00067014655
E40: Resultados acumulados | F40: 19 | G40: 69800061 | I40: 38570743 | K40: 27928180 | N40: =G40/G$43 -> 0.024919693 | P40: =I40/I$43 -> 0.016224144 | S40: =G40-I40 -> 31229319 | U40: =N40-P40 -> 0.0086955495
E41: Revalorización del patrimonio (ORI) | F41: 20 | G41: 51638296 | I41: 34288675 | K41: 28376140 | N41: =G41/G$43 -> 0.018435664 | P41: =I41/I$43 -> 0.014422963 | S41: =G41-I41 -> 17349622 | U41: =N41-P41 -> 0.0040127015
E42: Total patrimonio | G42: 2794154680 | I42: 2.3724067e+09 | K42: 1.22434e+09 | N42: =G42/G$43 -> 0.99755612 | P42: =I42/I$43 -> 0.99791357 | S42: =G42-I42 -> 421748000 | U42: =N42-P42 -> -0.00035745416
E43: Total pasivos + patrimonio | G43: 2801000000 | I43: 2.3773669e+09 | K43: 1.226486e+09 | N43: =G43/G$43 -> 1 | P43: =I43/I$43 -> 1 | S43: =G43-I43 -> 423633110 | U43: =N43-P43 -> 0
E45: Las notas adjuntas son parte integral de los estados financieros
C48: Joseph C. , Brenda A.
...

Sheet Estado de Resultados
E3: C M
E4: NIT.9000000000-9
E5: Bucaramabnga Santander Colombia
N6: ANÁLISIS VERTICAL | S6: ANÁLISIS HORIZONTAL
E7: Estado de Resultados Integral | N7: DIC 2025 % | P7: DIC 2024 % | S7: VARIABLE ABSOLUTA | U7: VARIABLE RELATIVA %
E8: (Cifras expresadas en pesos colombianos – COP)
E10: Concepto | F10: Nota | G10: Al 31 de diciembre 2025 | I10: Al 31 de diciembre 2024 | K10: Al 31 de diciembre 2023
G11: $ | I11: $ | K11: $
E12: Ingresos Operacionales | F12: 21 | G12: 185430750 | I12: 102560320 | K12: 69845210 | N12: 1 | P12: 1 | S12: =G12-I12 -> 82870430 | U12: =N12-P12 -> 0
E13: Costos de ventas | F13: 22 | G13: -68609377 | I13: -37947318 | K13: -25842727 | N13: =G13/G$12 -> -0.37 | P13: =I13/I$12 -> -0.37 | S13: =G13-I13 -> -30662059 | U13: =N13-P13 -> -1.20372e-09
E14: Resultado bruto | G14: 116821373 | I14: 64613002 | K14: 44002483 | N14: =G14/G$12 -> 0.63 | P14: =I14/I$12 -> 0.63 | S14: =G14-I14 -> 52208371 | U14: =N14-P14 -> -1.20372e-09
E15: Gastos operacionales
E16: Gastos administrativos | F16: 23 | G16: -38965780 | I16: -21551672 | K16: -14677032 | N16: =G16/G$12 -> -0.21013656 | P16: =I16/I$12 -> -0.21013655 | S16: =G16-I16 -> -17414108 | U16: =N16-P16 -> -8.578031e-09
E17: Gastos operación minera | F17: 24 | G17: -21845300 | I17: -19430500 | K17: -15860200 | N17: =G17/G$12 -> -0.1178084 | P17: =I17/I$12 -> -0.18945436 | S17: =G17-I17 -> -2414800 | U17: =N17-P17 -> 0.071645962
E18: Depreciación y amortización | F18: 25 | G18: -18740250 | I18: -9865430 | K18: -3985600 | N18: =G18/G$12 -> -0.10106333 | P18: =I18/I$12 -> -0.09619149 | S18: =G18-I18 -> -8874820 | U18: =N18-P18 -> -0.0048718449
E19: Resultado operacional | G19: 37270043 | I19: 13765400 | K19: 9479651 | N19: =G19/G$12 -> 0.20099171 | P19: =I19/I$12 -> 0.1342176 | S19: =G19-I19 -> 23504643 | U19: =N19-P19 -> 0.066774107
E21: Ingresos No Operacionales | F21: 26 | G21: 5420300 | I21: 3865200 | K21: 2145980 | N21: =G21/G$12 -> 0.029230858 | P21: =I21/I$12 -> 0.03768709 | S21: =G21-I21 -> 1555100 | U21: =N21-P21 -> -0.0084562315
E22: Gastos No Operacionales | F22: 27 | G22: -1145780 | I22: -845320 | K22: -520450 | N22: =G22/G$12 -> -0.0061790183 | P22: =I22/I$12 -> -0.008242174 | S22: =G22-I22 -> -300460 | U22: =N22-P22 -> 0.0020631557
E23: Resultado antes de impuestos | G23: 41544563 | I23: 16785280 | K23: 11105181 | N23: =G23/G$12 -> 0.22404355 | P23: =I23/I$12 -> 0.16366252 | S23: =G23-I23 -> 24759283 | U23: =N23-P23 -> 0.060381031
E25: Impuestos y Complementarios | F25: 28 | G25: -6845320 | I25: -4960210 | K25: -2145980 | N25: =G25/G$12 -> -0.036915776 | P25: =I25/I$12 -> -0.048363831 | S25: =G25-I25 -> -1885110 | U25: =N25-P25 -> 0.011448055
E26: Excedente neto | G26: 34699243 | I26: 11825070 | K26: 8959201 | N26: =G26/G$12 -> 0.18712777 | P26: =I26/I$12 -> 0.11529868 | S26: =G26-I26 -> 22874173 | U26: =N26-P26 -> 0.071829087
E28: Apropiación reserva legal (10%) | F28: 29 | G28: -3469924.3 | I28: -1182507 | K28: -895920 | N28: =G28/G$12 -> -0.018712777 | P28: =I28/I$12 -> -0.011529868 | S28: =G28-I28 -> -2287417.3 | U28: =N28-P28 -> -0.0071829087
E29: Resultado neto del ejercicio | G29: 31229319 | I29: 10642563 | K29: 8063281 | N29: =G29/G$12 -> 0.16841499 | P29: =I29/I$12 -> 0.10376882 | S29: =G29-I29 -> 20586756 | U29: =N29-P29 -> 0.064646178
E31: Las notas adjuntas son parte integral de los estados financieros
C34: Joseph C. , Brenda A.
C35: Representante Legal Contador Público

Sheet Indicadores Financieros
C3: C M
C4: NIT.9000000000-9
C5: Bucaramanga Santander Colombia
F7: FORMULA | J7: RESULTADO | K7: INTERPRETACIÓN
D8: RAZÓN CORRIENTE
E9: = | F9: Activo corriente | I9: = | J9: ='Estado Situación Financiera'!G17 -> 1019920170 | K9: =J9/J10 -> 148.99525 | L9: La empresa tiene alta capacidad para pagar sus obligaciones a corto plazo.
F10: Pasivo corriente | J10: ='Estado Situación Financiera'!G31 -> 6845320
D11: RPA(RATIO DE PRUEBA ACIDA)
E12: = | F12: Activo corriente - Inventarios | I12: = | J12: ='Estado Situación Financiera'!G17-'Estado Situación Financiera'!G15 -> 971304190 | K12: =J12/J13 -> 141.89318 | L12: La empresa puede cubrir sus deudas corrientes sin vender inventarios.
F13: Pasivo corriente | J13: ='Estado Situación Financiera'!G31 -> 6845320
D14: CT(CAPITAL DE TRABAJO)
E15: = | F15: Activo corriente - Pasivo corriente | I15: = | J15: ='Estado Situación Financiera'!G17-'Estado Situación Financiera'!G31 -> 1013074850 | L15: La empresa posee liquidez suficiente para operar.
D17: ROTACIÓN DE CUENTAS POR COBRAR
E18: = | F18: Ventas | I18: = | J18: ='Estado de Resultados'!G12 -> 185430750 | K18: =J18/J19 -> 3.4421815 | L18: La cartera se recupera aproximadamente 3 veces al año.
F19: Cuentas por cobrar | J19: ='Estado Situación Financiera'!G14 -> 53870125 | K19: veces
D20: DÍAS DE CARTERA A MANO
F21: 365 dias | J21: 365 | K21: =J21/J22 -> 106.03741 | L21: La empresa tarda cerca de 106 días en cobrar.
F22: Rotación de cuentas por cobrar | J22: =K18 -> 3.4421815
D23: ROTACIÓN DE INVENTARIOS
F24: Costos de venta | J24: ='Estado de Resultados'!G13 -> -68609377 | K24: =J24/J25 -> -1.4112515 | L24: El inventario rota lentamente durante el año.
F25: Inventario | J25: ='Estado Situación Financiera'!G15 -> 48615980
D26: DIAS DE ROTACIÓN
F27: 365 dias | J27: 365 | K27: =J27/J28 -> -258.63568 | L27: El inventario tarda alrededor de 259 días en venderse.
F28: Rotacion de inventarios | J28: =K24 -> -1.4112515
D29: ROTACIÓN DE ACTIVOS
F30: Ventas | J30: ='Estado de Resultados'!G12 -> 185430750 | K30: =J30/J31 -> 0.066201624 | L30: Los activos generan pocas ventas respecto a su valor.
F31: Activos totales | J31: ='Estado Situación Financiera'!G26 -> 2801000000 | K31: veces
D33: ROTACIÓN CUENTAS POR PAGAR
E34: = | F34: Costos de venta | I34: = | J34: ='Estado de Resultados'!G13 -> -68609377 | K34: =J34/J35 -> -10.022815 | L34: La empresa paga aproximadamente 10 veces al año sus cuentas
F35: Cuentas por pagar | J35: ='Estado Situación Financiera'!G30 -> 6845320 | K35: veces
D36: ENDEUDAMIENTO TOTAL
E37: = | F37: Pasivo total | I37: = | J37: ='Estado Situación Financiera'!G35 -> 6845320 | K37: =J37/J38 -> 0.0024438843 | L37: La empresa tiene muy bajo nivel de endeudamiento.
F38: Activo total | J38: ='Estado Situación Financiera'!G26 -> 2801000000
D39: ENDEDUDAMIENTO FINANCIERO
E40: = | F40: Obligaciones financieras | I40: = | J40: ='Estado Situación Financiera'!G33 -> 0 | K40: =J40/J41 -> 0 | L40: La empresa no presenta deuda financiera.
F41: Activos totales | J41: ='Estado Situación Financiera'!G26 -> 2801000000
D42: COBERTURA DE INTERESES
E43: = | F43: Utilidad operacional | I43: = | J43: ='Estado de Resultados'!G19 -> 37270043 | K43: 0 | L43: La empresa no presenta gastos financieros
F44: Gastos financieros | J44: 0
D45: ROA - RENTABILIDAD GENERAL
...
